<sdf version='1.9'>
  <model name='turtlebot3_waffle'>
    <link name='base_footprint'>
      <inertial>
        <pose>-0.006056477959657685 0 0.01926442051009627 0 0 0</pose>
        <mass>1.4969096</mass>
        <inertia>
          <ixx>0.01330968881636598</ixx>
          <ixy>-4.7576583000000001e-05</ixy>
          <ixz>0.00091064575365546732</ixz>
          <iyy>0.013913324787183729</iyy>
          <iyz>-3.5422299000000002e-06</iyz>
          <izz>0.018379012970817749</izz>
        </inertia>
      </inertial>
      <collision name='base_footprint_fixed_joint_lump__base_link_collision'>
        <pose>-0.064 0 0.057 0 0 0</pose>
        <geometry>
          <box>
            <size>0.266 0.266 0.094</size>
          </box>
        </geometry>
      </collision>
      <collision name='base_footprint_fixed_joint_lump__camera_link_collision_1'>
        <pose>0.067 0 0.111 0 0 0</pose>
        <geometry>
          <box>
            <size>0.012 0.132 0.02</size>
          </box>
        </geometry>
      </collision>
      <collision name='base_footprint_fixed_joint_lump__caster_back_left_link_collision_2'>
        <pose>-0.177 0.06400079632671074 0.005000000317068165 -1.57 0 0</pose>
        <geometry>
          <box>
            <size>0.03 0.009 0.02</size>
          </box>
        </geometry>
      </collision>
      <collision name='base_footprint_fixed_joint_lump__caster_back_right_link_collision_3'>
        <pose>-0.177 -0.06399920367328926 0.005000000317068165 -1.57 0 0</pose>
        <geometry>
          <box>
            <size>0.03 0.009 0.02</size>
          </box>
        </geometry>
      </collision>
      <collision name='base_footprint_fixed_joint_lump__base_scan_collision_4'>
        <pose>-0.049 0 0.1255 0 0 0</pose>
        <geometry>
          <cylinder>
            <length>0.0315</length>
            <radius>0.055</radius>
          </cylinder>
        </geometry>
      </collision>
      <visual name='base_footprint_fixed_joint_lump__base_link_visual'>
        <pose>-0.064 0 0.01 0 0 0</pose>
        <geometry>
          <mesh>
            <scale>0.001 0.001 0.001</scale>
            <uri>model://turtlebot3_description/meshes/bases/waffle_base.stl</uri>
          </mesh>
        </geometry>
        <material>
          <diffuse>0.5 0.5 0.5 1</diffuse>
          <ambient>0.5 0.5 0.5 1</ambient>
        </material>
      </visual>
      <visual name='base_footprint_fixed_joint_lump__camera_link_visual_1'>
        <pose>0.064 -0.065 0.104 1.57 -5.551115123125783e-17 1.57</pose>
        <geometry>
          <mesh>
            <scale>1 1 1</scale>
            <uri>model://turtlebot3_description/meshes/sensors/r200.dae</uri>
          </mesh>
        </geometry>
      </visual>
      <visual name='base_footprint_fixed_joint_lump__base_scan_visual_2'>
        <pose>-0.064 0 0.132 0 0 0</pose>
        <geometry>
          <mesh>
            <scale>0.001 0.001 0.001</scale>
            <uri>model://turtlebot3_description/meshes/sensors/lds.stl</uri>
          </mesh>
        </geometry>
        <material>
          <diffuse>0.375 0.375 0.375 1</diffuse>
          <ambient>0.375 0.375 0.375 1</ambient>
        </material>
      </visual>
    </link>
    <joint name='wheel_left_joint' type='revolute'>
      <pose relative_to='base_footprint'>0 0.144 0.033 -1.57 0 0</pose>
      <parent>base_footprint</parent>
      <child>wheel_left_link</child>
      <axis>
        <xyz>0 0 1</xyz>
        <limit>
          <lower>-10000000000000000</lower>
          <upper>10000000000000000</upper>
        </limit>
        <dynamics>
          <spring_reference>0</spring_reference>
          <spring_stiffness>0</spring_stiffness>
        </dynamics>
      </axis>
    </joint>
    <link name='wheel_left_link'>
      <pose relative_to='wheel_left_joint'>0 0 0 0 0 0</pose>
      <inertial>
        <pose>0 0 0 0 0 0</pose>
        <mass>0.02849894</mass>
        <inertia>
          <ixx>1.117558e-05</ixx>
          <ixy>-4.2369783000000002e-11</ixy>
          <ixz>-5.9381719000000002e-09</ixz>
          <iyy>1.1192413e-05</iyy>
          <iyz>-1.4400107e-11</iyz>
          <izz>2.0712558000000001e-05</izz>
        </inertia>
      </inertial>
      <collision name='wheel_left_link_collision'>
        <pose>0 0 0 0 0 0</pose>
        <geometry>
          <cylinder>
            <length>0.017999999999999999</length>
            <radius>0.033000000000000002</radius>
          </cylinder>
        </geometry>
      </collision>
      <visual name='wheel_left_link_visual'>
        <pose>0 0 0 1.57 0 0</pose>
        <geometry>
          <mesh>
            <scale>0.001 0.001 0.001</scale>
            <uri>model://turtlebot3_description/meshes/wheels/left_tire.stl</uri>
          </mesh>
        </geometry>
        <material>
          <diffuse>0.375 0.375 0.375 1</diffuse>
          <ambient>0.375 0.375 0.375 1</ambient>
        </material>
      </visual>
    </link>
    <joint name='wheel_right_joint' type='revolute'>
      <pose relative_to='base_footprint'>0 -0.144 0.033 -1.57 0 0</pose>
      <parent>base_footprint</parent>
      <child>wheel_right_link</child>
      <axis>
        <xyz>0 0 1</xyz>
        <limit>
          <lower>-10000000000000000</lower>
          <upper>10000000000000000</upper>
        </limit>
        <dynamics>
          <spring_reference>0</spring_reference>
          <spring_stiffness>0</spring_stiffness>
        </dynamics>
      </axis>
    </joint>
    <link name='wheel_right_link'>
      <pose relative_to='wheel_right_joint'>0 0 0 0 0 0</pose>
      <inertial>
        <pose>0 0 0 0 0 0</pose>
        <mass>0.02849894</mass>
        <inertia>
          <ixx>1.117558e-05</ixx>
          <ixy>-4.2369783000000002e-11</ixy>
          <ixz>-5.9381719000000002e-09</ixz>
          <iyy>1.1192413e-05</iyy>
          <iyz>-1.4400107e-11</iyz>
          <izz>2.0712558000000001e-05</izz>
        </inertia>
      </inertial>
      <collision name='wheel_right_link_collision'>
        <pose>0 0 0 0 0 0</pose>
        <geometry>
          <cylinder>
            <length>0.017999999999999999</length>
            <radius>0.033000000000000002</radius>
          </cylinder>
        </geometry>
      </collision>
      <visual name='wheel_right_link_visual'>
        <pose>0 0 0 1.57 0 0</pose>
        <geometry>
          <mesh>
            <scale>0.001 0.001 0.001</scale>
            <uri>model://turtlebot3_description/meshes/wheels/right_tire.stl</uri>
          </mesh>
        </geometry>
        <material>
          <diffuse>0.375 0.375 0.375 1</diffuse>
          <ambient>0.375 0.375 0.375 1</ambient>
        </material>
      </visual>
    </link>
    <frame name='camera_depth_optical_joint' attached_to='camera_depth_frame'>
      <pose>0 0 0 -1.57 -0 -1.57</pose>
    </frame>
    <frame name='camera_depth_optical_frame' attached_to='camera_depth_optical_joint'/>
    <frame name='camera_depth_joint' attached_to='camera_link'>
      <pose>0.005 0.028 0.013 0 -0 0</pose>
    </frame>
    <frame name='camera_depth_frame' attached_to='camera_depth_joint'/>
    <frame name='camera_rgb_optical_joint' attached_to='camera_rgb_frame'>
      <pose>0 0 0 -1.57 -0 -1.57</pose>
    </frame>
    <frame name='camera_rgb_optical_frame' attached_to='camera_rgb_optical_joint'/>
    <frame name='camera_rgb_joint' attached_to='camera_link'>
      <pose>0.005 0.018 0.013 0 -0 0</pose>
    </frame>
    <frame name='camera_rgb_frame' attached_to='camera_rgb_joint'/>
    <frame name='camera_joint' attached_to='base_link'>
      <pose>0.064 -0.065 0.094 0 -0 0</pose>
    </frame>
    <frame name='camera_link' attached_to='camera_joint'/>
    <frame name='caster_back_left_joint' attached_to='base_link'>
      <pose>-0.177 0.064 -0.004 -1.57 0 0</pose>
    </frame>
    <frame name='caster_back_left_link' attached_to='caster_back_left_joint'/>
    <frame name='caster_back_right_joint' attached_to='base_link'>
      <pose>-0.177 -0.064 -0.004 -1.57 0 0</pose>
    </frame>
    <frame name='caster_back_right_link' attached_to='caster_back_right_joint'/>
    <frame name='imu_joint' attached_to='base_link'>
      <pose>0 0 0.068 0 -0 0</pose>
    </frame>
    <frame name='imu_link' attached_to='imu_joint'/>
    <frame name='scan_joint' attached_to='base_link'>
      <pose>-0.064 0 0.122 0 -0 0</pose>
    </frame>
    <frame name='base_scan' attached_to='scan_joint'/>
    <frame name='base_joint' attached_to='base_footprint'>
      <pose>0 0 0.01 0 -0 0</pose>
    </frame>
    <frame name='base_link' attached_to='base_joint'/>
  </model>
</sdf>
